<?xml version="1.0"?>
<robot name="Machine">

  <material name="blue">
    <color rgba="0 0 0.8 1"/>
  </material>

  <material name="white">
    <color rgba="1 1 1 1"/>
  </material>

  <material name="yellow">
    <color rgba="1 1 0 1"/>
  </material>

  <material name="grey">
    <color rgba="0.66 0.66 0.66 1"/>
  </material>

  <link name="world"/>
  
  <link name="container"/>

  <link name="base">
    <visual>
	  <geometry>
	  	<mesh filename="package://autonomous_excavator/urdf/meshes/electrical/Base.STL" scale="0.001 0.001 0.001" />
	  </geometry>
      <material name="blue"/>
    </visual>
  </link>
  
  <link name="swing">
    <visual>
	  <geometry>
	  	<mesh filename="package://autonomous_excavator/urdf/meshes/electrical/Swing.STL" scale="0.001 0.001 0.001" />
	  </geometry>
      <material name="yellow"/>
    </visual>
  </link>
  
  <link name="boom">
    <visual>
	  <geometry>
	  	<mesh filename="package://autonomous_excavator/urdf/meshes/electrical/Boom.STL" scale="0.001 0.001 0.001" />
	  </geometry>
      <material name="yellow"/>
    </visual>
  </link>


  <link name="camera_bracket">
    <visual>
	  <geometry>
	  	<mesh filename="package://autonomous_excavator/urdf/meshes/electrical/CameraBracket.STL" scale="0.001 0.001 0.001" />
	  </geometry>
      <material name="white"/>
    </visual>
  </link>


  <link name="camera">
    <visual>
	  <geometry>
		  <mesh filename="package://autonomous_excavator/urdf/meshes/electrical/D455.STL" scale="0.001 0.001 0.001" />
	  </geometry>
      <material name="grey"/>
    </visual>
  </link>


  <link name="arm">
    <visual>
	  <geometry>
	  	<mesh filename="package://autonomous_excavator/urdf/meshes/electrical/Arm.STL" scale="0.001 0.001 0.001" />
	  </geometry>
      <material name="yellow"/>
    </visual>
  </link>

  <link name="bucket">
    <visual>
	  <geometry>
	  	<mesh filename="package://autonomous_excavator/urdf/meshes/electrical/Bucket.STL" scale="0.001 0.001 0.001" />
	  </geometry>
      <material name="yellow"/>
    </visual>
  </link>

  <joint name="fix" type="fixed">
  	<parent link="world"/>
	<child link="base"/>
  </joint>
  
  <joint name="container_fix" type="fixed">
      <!-- <origin xyz="1.200 -0.130 -0.750" rpy="0 0 0" /> -->
  	<origin xyz="1.200 -0.430 -0.750" rpy="0 0 0" />
  	<parent link="world"/>
	<child link="container"/>
  </joint>

  <joint name="camera_bracket_fix" type="fixed">
	<origin xyz="0.3872 0.0495 0.0985" rpy="0 0.1974 0" />
  	<parent link="boom"/>
	<child link="camera_bracket"/>
  </joint>

  <joint name="D455_fix" type="fixed">
	  <!-- <origin xyz="0.1065 0.0275 -0.0622" rpy="0.09 2.6180 0" /> -->
	<!-- <origin xyz="0.1665 0.0275 -0.0622" rpy="0.09 2.6180 0" /> -->
	<!-- <origin xyz="0.1665 0.0275 -0.0622" rpy="0.09 2.7180 0" /> -->
	<origin xyz="0.1465 0.0275 -0.0622" rpy="0.09 2.6880 0" />
  	<parent link="camera_bracket"/>
	<child link="camera"/>
  </joint>

  <joint name="Swing" type="continuous">
    <axis xyz="0.0 0.0 1.0" />
    <origin xyz="0.2548 0 0.247" rpy="0 0 0" />
    <parent link="base"/>
    <child link="swing"/>
  </joint>

  <joint name="Boom" type="continuous" >
    <axis xyz="0.0 1.0 .0" />
	<origin xyz="0.3445 0 0.063" rpy="0 0 0" />
    <parent link="swing"/>
    <child link="boom"/>
  </joint>

  <joint name="Arm" type="continuous">
    <axis xyz="0.0 1.0 .0" />
	<origin xyz="1.071 0 0" rpy="0 0 0" />
    <parent link="boom"/>
    <child link="arm"/>
  </joint>

  <joint name="Bucket" type="continuous">
    <axis xyz="0.0 1.0 .0" />
	<origin xyz="0.560 0.0 0.0" rpy="0 0 0" />
    <parent link="arm"/>
    <child link="bucket"/>
  </joint>

</robot>
